Workbook

Sheet DASHBOARD
B2: RELATÓRIO MENSAL | ABRIL/2026
B5: PROCESSOS ATIVOS | E5: EXPOSIÇÃO TOTAL | J5: PROCESSOS ENCERRADOS | M5: TAXA DE ÊXITO
B6: =COUNTA(TRABALHISTA!A5:A99) -> 6 | E6: 973877.75 | J6: =COUNTA('ARQUIVADOS '!A5:A100) -> 11 | M6: =IFERROR((COUNTIF('ARQUIVADOS '!I5:I100,"*acordo*")+COUNTIF('ARQUIVADOS '!I5:I100,"*improcedent*")+COUNTIF('ARQUIVADOS '!I5:I100,"*Extint*")+COUNTIF('ARQUIVADOS '!I5:I100,"*Exclusão*")+COUNTIF('ARQUIVADOS '!I5:I100,"*desistiu*"))/COUNTA('ARQUIVADOS '!A5:A100),0) -> 0.63636364
B7: em andamento | E7: valor da causa | J7: no período | M7: casos favoráveis
B9: ▎ ANÁLISE DE RISCO DOS PROCESSOS ATIVOS | J9: ▎ DISTRIBUIÇÃO POR RISCO
B10: PROCESSO | C10: RECLAMANTE | D10: VALOR (R$) | E10: RISCO | F10: FASE ATUAL | J10: CLASSIFICAÇÃO | K10: QTD | L10: VALOR (R$) | M10: % DO TOTAL
B11: 1001078-03.2024.5.02.0030 | C11: GLEICE S. O. SOUZA | D11: 120570.6 | E11: PROVÁVEL | F11: Recurso de Revista / TST | J11: ● PROVÁVEL | K11: =COUNTIF(TRABALHISTA!I5:I99,"PROVÁVEL") -> 2 | L11: 199404.47 | M11: =IFERROR(K11/K14,0) -> 0.33333333
B12: 1001957-28.2024.5.02.0606 | C12: TELMA S. O. DOS SANTOS | D12: 250205.78 | E12: POSSÍVEL | F12: Aguardando 2º Grau | J12: ● POSSÍVEL | K12: =COUNTIF(TRABALHISTA!I5:I99,"POSSÍVEL") -> 3 | L12: 693343.08 | M12: =IFERROR(K12/K14,0) -> 0.5
B13: 1001141-91.2025.5.02.0612 | C13: CAROLLINY B. VIEIRA | D13: 78833.87 | E13: PROVÁVEL | F13: Aguardando 2º Grau | J13: ● REMOTO | K13: =COUNTIF(TRABALHISTA!I5:I99,"REMOTO") -> 1 | L13: 81130.2 | M13: =IFERROR(K13/K14,0) -> 0.16666667
B14: 1000957-91.2025.5.02.0077 | C14: ANTONIO D. M. DA SILVA | D14: 81130.2 | E14: REMOTO | F14: Aguardando Arquivamento | J14: TOTAL | K14: =SUM(K11:K13) -> 6 | L14: =SUM(L11:L13) -> 973877.75 | M14: 1
B15: 1000436-74.2026.5.02.0607 | C15: ROSIMEIRE S. MARTINS | D15: 150337.52 | E15: POSSÍVEL | F15: Audiência Una 23/04/2026
B16: 0010391-37.2026.5.15.0106 | C16: CATIA CILENE AIELLO | D16: 292799.78 | E16: POSSÍVEL | F16: Audiência Inicial 29/07/2026
B18: ▎ PROCEDIMENTOS ADMINISTRATIVOS
B19: PROCESSO | C19: DESCRIÇÃO | D19: ÓRGÃO | E19: CIDADE | F19: STATUS | G19: RESULTADO
B20: 14152.083144/2025-21 | C20: Auto de infração - Menor Aprendiz | D20: MTE | E20: São Paulo | F20: Defesa Apresentada | G20: Aguardando Decisão
B22: ▎ PROCESSOS ARQUIVADOS / ENCERRADOS | J22: ▎ INDICADORES-CHAVE
B23: PROCESSO | C23: RECLAMANTE | D23: ENCERRAMENTO | E23: DESFECHO | F23: VALORES (R$)
B24: 1000562-20.2023.5.02.0611 | C24: SANDRA C. DA SILVA | D24: dez/23 | E24: Acordo | F24: 41329.6 | J24: TOTAL DE PROCESSOS GERIDOS | K24: =B6+J6 -> 17
B25: 1000920-22.2022.5.02.0610 | C25: LILIANE V. DOS REIS | D25: out/22 | E25: Acordo | F25: 6000 | J25: ativos + encerrados
B26: 1001872-61.2023.5.02.0611 | C26: GENEZINA C. DA SILVA | D26: abr/24 | E26: Arquivado | F26: 80873.4
B27: 1001707-41.2023.5.02.0602 | C27: MAICON F. DE OLIVEIRA | D27: mai/24 | E27: Arquivado | F27: 81990.23 | J27: VALOR TOTAL EM ACORDOS | K27: 83920.28
B28: 1002282-94.2024.5.02.0608 | C28: TAMIRIS O. RAMOS | D28: 46047 | E28: Acordo Extrajudicial | F28: 3295.34 | J28: pagos em acordos judiciais
B29: 0001196-10.2024.5.09.0124 | C29: ERALDO N. G. JUNIOR | D29: 46047 | E29: Acordo (Exclusão Apdata) | F29: 0
B30: 1002139-63.2024.5.02.0040 | C30: TAMIRIS O. RAMOS | D30: 46106 | E30: Acordo | F30: 33295.34 | J30: TEMPO MÉDIO DE RESOLUÇÃO | K30: ~18 meses
B31: 1000410-32.2025.5.02.0051 | C31: CAROLLINY B. VIEIRA | D31: mai/25 | E31: Extinção s/ Mérito | F31: 0 | J31: estimativa média dos processos encerrados
B32: 1001516-86.2025.5.02.0614 | C32: MIKAELLA A. M. DA SILVA | D32: set/25 | E32: Condenação (Multa 477) | F32: 4599.38
B33: TOTAL PAGAMENTOS | F33: =SUM(F24:F32) -> 251383.29 | J33: RISCO PREDOMINANTE | K33: POSSÍVEL
J34: 3 de 6 processos ativos
J36: CONDENAÇÕES EFETIVAS | K36: 1
J37: multa art. 477 CLT — R$ 4.599,38
B39: ▎ PRINCIPAIS PEDIDOS RECORRENTES | J39: ▎ STATUS / PRÓXIMOS PASSOS
B40: PEDIDO | D40: OCORRÊNCIAS | E40: FREQUÊNCIA | K40: PROCESSO | L40: STATUS / PRÓXIMA AÇÃO
B41: Horas Extras e Reflexos | D41: 5 | E41: 0.83 | J41: ⏳ | K41: 1001078-03...0030 | L41: Sobrestado — Aguardando IRR nº 33 no TST
B42: Responsabilidade Subsidiária/Solidária | D42: 4 | E42: 0.67 | J42: ⏳ | K42: 1001957-28...0606 | L42: Recurso Ordinário — Aguardando 2º Grau
B43: Verbas Rescisórias | D43: 4 | E43: 0.67 | J43: ⏳ | K43: 1001141-91...0612 | L43: Recurso Ordinário — 11ª Turma TRT-2
B44: Adicional de Insalubridade/Periculosidade | D44: 4 | E44: 0.67 | J44: ⏳ | K44: 1000957-91...0077 | L44: Arquivamento — Ausência do Reclamante
B45: Danos Morais | D45: 3 | E45: 0.5 | J45: ⏳ | K45: 1000436-74...0607 | L45: Audiência Una em 23/04/2026
B46: Rescisão Indireta | D46: 2 | E46: 0.33 | J46: ⏳ | K46: 0010391-37...0106 | L46: Audiência Inicial em 29/07/2026
B47: Nulidade Banco de Horas | D47: 2 | E47: 0.33
B49: ▎ DECISÕES JUDICIAIS POR INSTÂNCIA | J49: ▎ EVOLUÇÃO PROCESSUAL
...

Sheet TRABALHISTA
A1: PROCESSOS JUDICIAIS TRABALHISTAS
A3: PROCESSO Nº | B3: JUÍZO | C3: ÓRGÃO | D3: DATA DE INSTAURAÇÃO | E3: PARTES ENVOLVIDAS | G3: VALOR | H3: PRINCIPAIS FATOS | I3: RISCO DE PERDA | J3: STATUS MENSAL | K3: OBS
E4: RECLAMADA | F4: RECLAMANTE
A5: 1001078-03.2024.5.02.0030 | B5: 7ª VARA DO TRABALHO DE SÃO PAULO - ZONA LESTE | C5: TRT 2ª REGIÃO | D5: 45471 | E5: CENTRO SANEAMENTO E SERVICOS AVANCADOS LTDA (1ª RECLAMADA); ASSOCIACAO DOS LOJISTAS DO SHOPPING JARDIM ANALIA FRANCO (2ª RECLAMADA); HOSPITAL AVICCENA S/A (3ª RECLAMADA); SAO PAULO FUTEBOL CLUBE (4ª RECLAMADA); SHOPPING CENTER LESTE COMERCIAL LIMITADA (5ª RECLAMADA) E APDATA DO BRASIL SOFTWARE LTDA (6ª RECLAMADA). | F5: GLEICE STEFANE OLIVEIRA SOUZA | G5: 120570.6 | H5: Trata-se de reclamação trabalhista ajuizada pela reclamante em face da empresa Centro Saneamentos, com responsabilidade subsidiária atribuída às tomadoras de serviços (Shopping Anália Franco, Hospital Central do Tatuapé – Aviccena, Estádio Morumbi, Shopping Aricanduva e Apdata). Na ação, a reclamante formula pedidos de: Pagamento de horas extras e reflexos; Remuneração pelo intervalo intrajornada suprimido; Diferenças de FGTS + 40%; Indenização de PLR não paga; Aplicação de multas normativas por descumprimento de convenções coletivas; Devolução de descontos indevidos de contribuição assistencial; Pagamento de adicional de insalubridade e periculosidade; Devolução de descontos indevidos em razão de faltas justificadas; Indenização por danos morais decorrentes de perseguições e humilhações sofridas; Reconhecimento da rescisão indireta do contrato de trabalho; Anotação/retificação da CTPS e entrega do PPP; Condenação das reclamadas em honorários advocatícios; e responsabilização subsidiária das tomadoras de serviços. Em síntese, a ação busca a rescisão indireta com o pagamento das verbas rescisórias, indenizações e demais direitos trabalhistas não adimplidos. | I5: PROVÁVEL | J5: Na audiência inaugural foi determinada a realização de perícia para apuração de insalubridade, tendo as partes apresentado seus quesitos. O laudo pericial concluiu pela existência de insalubridade em grau máximo (40%). Foram apresentadas impugnações ao laudo. Na audiência de instrução, procedeu-se à oitiva das partes, não havendo produção de prova testemunhal. Em seguida, ambas as partes apresentaram razões finais. Em 08/07/2025, foi prolatada sentença pela juíza Priscila Basilio Minikoski Aldinucci, que julgou parcialmente procedentes os pedidos formulados pelo reclamante, declarando: a responsabilidade subsidiária da 5ª e da 6ª reclamadas; o reconhecimento da rescisão indireta; o pagamento das verbas rescisórias (saldo de salário, aviso prévio, férias, 13º salário e indenização de 40% sobre o FGTS); adicional de insalubridade; PLR referente aos anos de 2022 e 2023; multa normativa. O valor da condenação foi fixado em R$ 20.000,00. A 1ª reclamada interpôs recurso ordinário, tendo o reclamante apresentado contrarrazões. O processo encontra-se aguardando distribuição no 2º grau para julgamento do recurso ordinário. O processo foi distribuído à 8ª Turma, sob relatoria da desembargadora Cynthia Gomes Rosa. Em 02/12/2025, foi proferido acórdão que manteve integralmente a sentença de 1º grau. A 1ª reclamada interpôs recurso de revista. Em 09/02/2026, foi publicada decisão determinando o sobrestamento do processo, considerando que o recurso de revista interposto pela 1ª reclamada versa sobre o tema objeto do IRR nº 33. | K5: Conforme informado por e-mail em 19/09/2024, o caso foi classificado com risco provável, em razão do pedido de responsabilidade subsidiária. Os cálculos liquidados perfazem o montante de R$ 18.937,66, na data-base de 30/09/2024. Para fins de estimativa de eventual condenação subsidiária, foram considerados os pedidos de verbas rescisórias e indenização por danos morais.
A6: 1001957-28.2024.5.02.0606 | B6: 6ª VARA DO TRABALHO DE SÃO PAULO - ZONA LESTE | C6: TRT 2ª REGIÃO | D6: 45553 | E6: CENTRO SANEAMENTO E SERVICOS AVANCADOS LTDA (1ª RECLAMADA); CONDOMINIO COMERCIAL SHOPPING PATIO HIGIENOPOLIS (2ª RECLAMADA); WEBEDIA INTERNET BRASIL S.A. (3ª RECLAMADA) E APDATA DO BRASIL SOFTWARE LTDA (4ª RECLAMADA). | F6: TELMA DE SOUZA OLIVEIRA DOS SANTOS | G6: R$ 250.205,78 | H6: Trata-se de reclamação trabalhista ajuizada pela reclamante em face da empresa Centro Saneamento, com responsabilidade subsidiária atribuída às tomadoras de serviços Shopping Pátio Higienópolis, Webdia e Apdata. Na ação, a reclamante formula pedidos de: reconhecimento da rescisão indireta do contrato de trabalho; pagamento das verbas rescisórias (saldo de salário, aviso prévio, férias proporcionais + 1/3, 13º salário proporcional, FGTS + 40% e seguro-desemprego); diferenças salariais pelo não recebimento de salário substituição durante cobertura de férias de encarregada; adicional por acúmulo de funções, estimado em 30% da remuneração, com reflexos em demais verbas; pagamento de adicional de insalubridade em grau máximo, com reflexos e entrega de PPP/LTCAT; pagamento de adicional de periculosidade e suas integrações; reconhecimento da responsabilidade subsidiária das tomadoras de serviços; anotação/baixa na CTPS e obrigação de fazer quanto às guias de FGTS e seguro-desemprego; concessão da gratuidade da justiça. Em síntese, a ação busca a rescisão indireta do contrato, o pagamento integral das verbas rescisórias, indenizações e adicionais decorrentes de irregularidades contratuais e condições de trabalho insalubres, além da responsabilização subsidiária das empresas tomadoras dos serviços. | I6: POSSÍVEL | J6: Na audiência inaugural foi determinada a realização de perícia para apuração de insalubridade e periculosidade, tendo as partes apresentado seus quesitos. O laudo pericial concluiu pela inexistência de insalubridade e periculosidade, sendo posteriormente apresentadas impugnações. Na audiência de instrução, procedeu-se à oitiva das partes. A reclamante apresentou como testemunha Maria Nunes do Nascimento, única testemunha ouvida, não havendo outras. Nenhuma das reclamadas apresentou testemunhas. Em seguida, ambas as partes apresentaram razões finais. Em 19/03/2025, foi prolatada sentença pelo juiz Ivo Roberto Santarém Teles, que julgou improcedentes os pedidos formulados pela reclamante. A reclamante interpôs recurso ordinário, tendo as reclamadas apresentado contrarrazões. O processo encontra-se atualmente aguardando distribuição no 2º grau para julgamento do recurso ordinário. O processo foi distribuído para a 14ª Turma, sob a relatoria do Desembargador Ricardo Nino Ballarini. Em 09/06/2025, foi publicado acórdão que deu parcial provimento ao recurso da reclamante, reformando a sentença de origem e julgando parcialmente procedentes os pedidos. A reclamada opôs embargos de declaração, posteriormente rejeitados em acórdão publicado em 12/08/2025. Na sequência, a 1ª reclamada interpôs recurso de revista, cujo seguimento foi denegado em decisão publicada em 13/10/2025. Contra essa decisão, a 1ª reclamada apresentou agravo de instrumento. Distribuído no TST para a 7ª Turma, sob a relatoria do Ministro José Pedro de Camargo Rodrigues de Souza, encontrando-se o processo atualmente aguardando julgamento do referido agravo.
A7: 1001141-91.2025.5.02.0612 | B7: 12ª VARA DO TRABALHO DE SÃO PAULO - ZONA LESTE | C7: TRT 2ª REGIÃO | D7: 45805 | E7: HR INOVE MAO DE OBRA TEMPORARIA LTDA - ME (1ª RECLAMADA); LIFE RECURSOS HUMANOS LTDA (2ª RECLAMADA) E APDATA DO BRASIL SOFTWARE LTDA (3ª RECLAMADA) | F7: CAROLLINY BARCELONI VIEIRA | G7: 78833.87 | H7: Trata-se de reclamação trabalhista ajuizada pela reclamante em face das empresas HR I/nove, Life Recursos e Apdata. Na ação, a reclamante formula pedidos de: reconhecimento da unicidade contratual e do vínculo direto com a Apdata, desde 16/12/2021 até 01/08/2023, com responsabilidade solidária das demais reclamadas; pagamento de horas extras habituais, com reflexos em férias, 13º salário, FGTS + 40% e demais verbas, além da nulidade de eventual banco de horas; indenização por atraso no pagamento do salário-maternidade prorrogado; indenização por danos morais e assédio moral, em razão de condutas abusivas e humilhantes sofridas no ambiente de trabalho; pagamento das verbas rescisórias decorrentes da dispensa sem justa causa (saldo de salário, aviso prévio, férias proporcionais + 1/3, 13º proporcional, FGTS + 40% e seguro-desemprego); concessão da justiça gratuita; condenação ao pagamento de honorários de sucumbência; aplicação de correção monetária pelo IPCA-E e juros de mora; regularização dos recolhimentos previdenciários e fiscais. Em síntese, a ação busca o reconhecimento do vínculo direto com a tomadora de serviços, a reparação por irregularidades contratuais e abusos sofridos, além do pagamento integral das verbas trabalhistas e indenizatórias. | I7: PROVÁVEL | J7: Na audiência instrutória, procedeu-se à oitiva das partes. A reclamante apresentou como testemunha Cleber Teles Camargo, enquanto a Apdata apresentou como testemunha Katia Alves da Silva. Em seguida, ambas as partes apresentaram razões finais. Em 25/10/2025, foi prolatada sentença pela juíza Bartira Barros Salmom de Souza, que julgou parcialmente procedentes os pedidos formulados pela reclamante, declarando: o vínculo empregatício com a 1ª reclamada no período de 16/12/2021 a 01/08/2023; a responsabilidade solidária da 2ª e 3ª reclamadas no pagamento de indenização por danos morais; a condenação da Apdata à anotação da CTPS da reclamante. O valor da condenação foi fixado em R$ 7.746,79. A Apdata interpôs recurso ordinário, tendo a reclamante apresentado contrarrazões. O processo foi distribuído ao 2º grau, para a 11ª Turma, sob relatoria do desembargador Waldir dos Santos Ferro, encontrando-se atualmente aguardando julgamento do recurso ordinário. | K7: Conforme informado por e-mail em 19/09/2025, o caso foi classificado com risco provável, em razão do pedido de responsabilidade subsidiária. A reclamante alega que era compelida a laborar além da jornada, especialmente em períodos de fechamento de folha de pagamento, chegando a trabalhar até 21h30 e, em média, duas vezes por semana até 23h00. Sustenta que não houve o devido pagamento das horas extras, bem como a ocorrência de fraude no controle de ponto. Alega ainda a prática de assédio moral por sua coordenadora e atraso no pagamento do salário-maternidade. Postula a nulidade do banco de horas, aplicação de multa pelo atraso no pagamento do salário-maternidade e afirma que recebia ordens e atuava como preposta da 3ª reclamada.
A8: 1000957-91.2025.5.02.0077 | B8: 77ª VARA DO TRABALHO DE SÃO PAULO | C8: TRT 2ª REGIÃO | D8: 45824 | E8: APDATA DO BRASIL SOFTWARE LTDA | F8: ANTONIO DONIZETE MARIANO DA SILVA | G8: R$ 81.130,20 | H8: Trata-se de reclamação trabalhista ajuizada pelo reclamante em face da reclamada. Na ação, o reclamante formula pedidos de: reconhecimento do desvio de função, pois contratado como porteiro passou a exercer também atividades de vigilante sem a devida contraprestação; pagamento das diferenças salariais decorrentes do desvio de função, com reflexos em férias + 1/3, 13º salário, FGTS + 40% e verbas rescisórias; pagamento do adicional de periculosidade pelo exercício da função de vigilante, com reflexos em férias, 13º salário e FGTS + 40%; retificação da CTPS para constar corretamente a função exercida; condenação da reclamada ao pagamento de honorários advocatícios; responsabilização da reclamada pelos recolhimentos previdenciários e fiscais; aplicação da correção monetária desde o mês da prestação dos serviços; tramitação pelo Juízo 100% digital e intimação pessoal do autor para audiência. Em síntese, a ação busca o reconhecimento do desvio de função e o pagamento das diferenças salariais e adicionais devidos, além das verbas rescisórias, reflexos legais e indenizações correspondentes. | I8: REMOTO | J8: Em audiência realizada em 15/09/2025, foi determinado o arquivamento dos autos, em razão da ausência injustificada da parte reclamante. O processo encontra-se atualmente aguardando o arquivamento definitivo.
A9: 1000436-74.2026.5.02.0607 | B9: 7ª VARA DO TRABALHO DE SÃO PAULO - ZONA LESTE | C9: TRT 2ª REGIÃO | D9: 46080 | E9: APDATA DO BRASIL SOFTWARE LTDA | F9: ROSIMEIRE SOUZA MARTINS | G9: 150337.52 | H9: Trata-se de reclamação trabalhista ajuizada pela reclamante em face da reclamada. Na ação, a reclamante formula pedidos de: concessão dos benefícios da justiça gratuita, com alegação de inconstitucionalidade dos arts. 790-B, 791-A §§3º e 4º e 844 da CLT; reconhecimento do vínculo contratual como Analista de Suporte Técnico de 20/02/2021 a 01/03/2024, com salário de R$ 3.305,02; pagamento de horas extras habituais (em média 40 minutos a 1h adicional, três vezes por semana), com adicionais previstos em norma coletiva (75% e 100%), e reflexos em férias + 1/3, 13º salário, FGTS + 40%, aviso prévio e DSR; declaração de nulidade do banco de horas, por ausência de transparência e descumprimento da convenção coletiva, com conversão em horas extras remuneradas; pagamento de adicional de periculosidade de 30% sobre a remuneração, em razão da exposição contínua a tanques de óleo diesel (cerca de 2.000 litros) em gerador instalado no prédio, com reflexos em todas as verbas salariais e rescisórias; emissão da guia PPP (Perfil Profissiográfico Previdenciário); condenação da reclamada ao pagamento de custas, honorários advocatícios e encargos legais. Em síntese, a ação busca o reconhecimento de irregularidades na jornada e no banco de horas, o pagamento de horas extras e adicional de periculosidade, além da concessão da justiça gratuita e indenizações decorrentes. | I9: POSSÍVEL | J9: Foi designada audiência una para o dia 23/04/2026, às 08h00.
A10: 0010391-37.2026.5.15.0106 | B10: CON1 - ARARAQUARA | C10: TRT 15ª REGIÃO | D10: 46086 | E10: APDATA DO BRASIL SOFTWARE LTDA (1ª RECLAMADA) E SERASA S/A (2ª RECLAMADA) | F10: CATIA CILENE AIELLO | G10: 292799.78 | H10: Trata-se de reclamação trabalhista ajuizada pela reclamante em face da empresa Apdata, com responsabilidade subsidiária atribuída à Serasa. Na ação, a reclamante formula pedidos de: reconhecimento da jornada extraordinária habitual, com pagamento de horas extras, adicionais noturnos e diferenças de intervalos intrajornada e interjornada, com reflexos em férias + 1/3, 13º salários, aviso prévio, DSR, FGTS + 40%; declaração de nulidade do banco de horas, por manipulação dos registros de ponto e ausência de compensação efetiva; indenização por dispensa discriminatória, ocorrida logo após afastamento médico por crises de ansiedade e pânico, configurando violação da Súmula 443 do TST e da Lei nº 9.029/95; indenização por danos morais, em razão de jornadas exaustivas, supressão do direito à desconexão, exposição indevida em grupo de colegas e agravamento de quadro de saúde; responsabilização das reclamadas pelo pagamento das verbas trabalhistas e indenizatórias; concessão da justiça gratuita e inversão do ônus da prova quanto aos controles de jornada. Em síntese, a ação busca reparação por excesso de jornada, manipulação de ponto, nulidade do banco de horas, reconhecimento da dispensa discriminatória e indenização por danos morais, além do pagamento integral das verbas trabalhistas devidas. | I10: POSSÍVEL | J10: Foi designada audiência inicial por videoconferência para o dia 29/07/2026, às 09h10.

Sheet PROCEDIMENTOS ADM
A1: PROCESSO ADMINISTRATIVO
A3: NÚMERO DO PROCESSO | B3: Assunto | C3: AÇÃO | D3: CONTRÁRIO PRINCIPAL | E3: CIDADE | F3: VARA/TURMA | G3: DEFESA APRESENTADA | H3: STATUS ATUAL
A4: 14152.083144/2025-21 | B4: Menor Aprendiz | C4: Auto de infração | D4: Ministério do Trabalho e Emprego | E4: São Paulo | F4: MTE | G4: Sim | H4: Apresentamos defesa.

Sheet ARQUIVADOS 
A1: PROCESSOS JUDICIAIS TRABALHISTAS
A3: PROCESSO Nº | B3: JUÍZO | C3: ÓRGÃO | D3: DATA DE INSTAURAÇÃO | E3: PARTES ENVOLVIDAS | G3: VALOR | H3: PRINCIPAIS FATOS | I3: STATUS
E4: RECLAMADA | F4: RECLAMANTE
A5: 1000562-20.2023.5.02.0611 | B5: 11ª VARA DO TRABALHO DE SÃO PAULO - ZONA LESTE | C5: TRT 2ª REGIÃO | D5: 45014 | E5: CENTRO SANEAMENTO E SERVICOS AVANCADOS S.A e APDATA DO BRASIL SOFTWARE LTDA | F5: SANDRA CIPRIANO DA SILVA | G5: 41329.6 | H5: Trata-se de reclamação trabalhista visando a rescisão indireta do contrato de trabalho, verbas rescisórias decorrentes e responsabilidade subsidiária da APDATA. | I5: Arquivado em 13/12/2023 - quitadas as parcelas do acordo.
A6: 1000920-22.2022.5.02.0610 | B6: 10ª VARA DO TRABALHO DE SÃO PAULO - ZONA LESTE | C6: TRT 2ª REGIÃO | D6: 44712 | E6: APDATA DO BRASIL SOFTWARE LTDA | F6: LILIANE VIEIRA DOS REIS VILELA | G6: R$ 6.000,00 | H6: Trata-se de reclamação trabalhista visando ao reconhecimento de estabilidade e reintegração da reclamante. | I6: Arquivado em 03/10/2022 - quitadas as parcelas do acordo.
A7: 1001872-61.2023.5.02.0611 | B7: 11ª VARA DO TRABALHO DE SÃO PAULO - ZONA LESTE | C7: TRT 2ª REGIÃO | D7: 45202 | E7: APDATA DO BRASIL SOFTWARE LTDA | F7: GENEZINA CALIXTO DA SILVA | G7: R$ 80.873,40 | H7: Trata-se de reclamação trabalhista visando Indenização correspondente ao pagamento dos salários do período denominado limbo previdenciário, qual seja, 02\12\2022 até 08\05\2023;Horas extras e reflexos;Diferenças das verbas rescisórias; Férias vencidas; 13º salário 2022 e 2023; Descontos indevidos no TRCT;Diferenças FGTS e multa; Indenização por dano moral e Honorários sucumbenciais; | I7: Arquivado em 18/04/2024
A8: 1001707-41.2023.5.02.0602 | B8: 02ª VARA DO TRABALHO DE SÃO PAULO - ZONA LESTE | C8: TRT 2ª REGIÃO | D8: 45188 | E8: APDATA DO BRASIL SOFTWARE LTDA | F8: MAICON FERNANDO DE OLIVEIRA | G8: R$ 81.990,23 | H8: Trata-se de reclamação trabalhista visando limbo previdenciário e verbas consectárias, horas extras e reflexos e FGTS. | I8: Arquivado em 03/05/2024
A9: 1002282-94.2024.5.02.0608 | B9: 26ª Vara do Trabalho de São Paulo | C9: TRT 2ª REGIÃO | D9: 45597 | E9: APDATA DO BRASIL SOFTWARE LTDA | F9: TAMIRIS ORLANDO RAMOS | G9: R$ 3.295,34 | H9: Trata-se de ação de homologação de acordo extrajudicial. | I9: Arquivado em 06/01/2025
A10: 0001196-10.2024.5.09.0124 | B10: 4ª Vara do Trabalho de Ponta Grossa | C10: TRT 9ª REGIÃO | D10: 45610 | E10: PASQUALI SOLUTION SOLUCOES EM INFORMATICA S/A e APDATA DO BRASIL SOFTWARE LTDA | F10: ERALDO NERAS GONCALVES JUNIOR | G10: 325565.72 | H10: Trata-se de reclamação trabalhista visando ao reconhecimento de vínculo empregatício, pagamento de danos morais, responsabilidade subsidiária/solidária, depósitos de FGTS, verbas rescisórias e multa do art. 477 CLT. | I10: Audiência inicial realizada em 30/01/2025, celebrado acordo entre reclamante e 1ª reclamada (Pasquali), no valor de R$100.000,00 em 9 parcelas. Exclusão do polo para APDATA. Trânsito em julgado em 30/01/2025.
A11: 1002139-63.2024.5.02.0040 | B11: 40ª Vara do Trabalho de São Paulo | C11: TRT 2ª REGIÃO | D11: 45643 | E11: APDATA DO BRASIL SOFTWARE LTDA | F11: TAMIRIS ORLANDO RAMOS | G11: 192216.9 | H11: Trata-se de reclamação trabalhista visando ao pagamento das férias, multa do art. 477 CLT, horas extras, adicional noturno, adicional de transferência, acúmulo de função, salário período de estabilidade e danos morais. | I11: Audiência inicial realizada em 27/02/2025, celebrado acordo entre as partes no valor de R$ 33.295,34, em duas parcelas, sendo a última em 10/03/2025. Acordo cumprido - arquivado em 12/03/2025.
A12: 1000410-32.2025.5.02.0051 | B12: 51ª Vara do Trabalho de São Paulo | C12: TRT 2ª REGIÃO | D12: 45733 | E12: HR INOVE MAO DE OBRA TEMPORARIA LTDA - ME, LIFE RECURSOS HUMANOS LTDA. e APDATA DO BRASIL SOFTWARE LTDA. | F12: CAROLLINY BARCELONI VIEIRA | G12: 65000 | H12: Trata-se de reclamação trabalhista visando ao reconhecimento de vínculo empregatício com 3ª reclamada (APDATA), responsabilidade solidária / subsidiária, pagamento de horas extras e indenização por dano moral - assédio moral. | I12: Audiência realizada em 21/05/2025,onde a reclamante desistiu da ação. Extinto o processo, sem resolução do mérito, nos termos do art. 485, VIII, do CPC.
A13: 1001516-86.2025.5.02.0614 | B13: 68ª VARA DO TRABALHO DE SÃO PAULO | C13: TRT 2ª REGIÃO | D13: 45849 | E13: APDATA DO BRASIL SOFTWARE LTDA | F13: MIKAELLA APARECIDA MENDONÇA DA SILVA | G13: R$ 4.023,59 | H13: Trata-se de reclamação trabalhista ajuizada pela reclamante em face da reclamada. Na ação, a reclamante formula pedidos de: concessão dos benefícios da justiça gratuita; reconhecimento do atraso no pagamento das verbas rescisórias, com aplicação da multa prevista no art. 477, §8º da CLT, equivalente a um salário (R$ 4.023,59); condenação da reclamada ao pagamento de honorários advocatícios de sucumbência no percentual de 15% sobre o valor da condenação; apresentação de documentos (contrato de trabalho, folhas de pagamento e comprovantes da rescisão); produção de provas documentais e testemunhais; condenação da reclamada ao pagamento das custas e despesas processuais. Em síntese, a ação busca a aplicação da multa do art. 477 da CLT em razão da mora no pagamento das verbas rescisórias, além de honorários advocatícios e demais encargos legais. | I13: REMOTO | J13: Na audiência instrutória, não houve a oitiva das partes, sendo o processo encaminhado diretamente para julgamento. Em 16/09/2025, foi prolatada sentença que julgou parcialmente procedentes os pedidos formulados pela reclamante, condenando a reclamada ao pagamento da multa prevista no art. 477, § 8º, da CLT, enquanto os demais pedidos foram julgados improcedentes. Como nenhuma das partes interpôs recurso, ocorreu o trânsito em julgado da ação, iniciando-se a fase de execução. As partes apresentaram seus cálculos de liquidação e, em decisão, o juiz homologou os cálculos da reclamante. A reclamada efetuou o pagamento no valor de R$ 4.599,38. Considerando que a execução foi integralmente satisfeita e o valor liberado, foi determinado o arquivamento definitivo do feito.
A14: 1000357-44.2022.5.02.0055
A15: 1001852-22.2022.5.02.0606
